Run python API_Generator.py
Traceback (most recent call last):
  File "/home/runner/work/tamil-news/tamil-news/API_Generator.py", line 73, in <module>
üöÄ Launching browser...
üîó Navigating to OpenAI signup page...
‚úâÔ∏è Entering email address...
    automate_openai_signup()
  File "/home/runner/work/tamil-news/tamil-news/API_Generator.py", line 15, in automate_openai_signup
    page.fill('input[type="email"]', 'user@example.com')
  File "/opt/hostedtoolcache/Python/3.11.12/x64/lib/python3.11/site-packages/playwright/sync_api/_generated.py", line 10147, in fill
    self._sync(
  File "/opt/hostedtoolcache/Python/3.11.12/x64/lib/python3.11/site-packages/playwright/_impl/_sync_base.py", line 115, in _sync
    return task.result()
           ^^^^^^^^^^^^^
  File "/opt/hostedtoolcache/Python/3.11.12/x64/lib/python3.11/site-packages/playwright/_impl/_page.py", line 872, in fill
    return await self._main_frame.fill(**locals_to_params(locals()))
           ^^^^^^^^^^^^^^^^^^^^^^^^^^^^^^^^^^^^^^^^^^^^^^^^^^^^^^^^^
  File "/opt/hostedtoolcache/Python/3.11.12/x64/lib/python3.11/site-packages/playwright/_impl/_frame.py", line 527, in fill
    await self._channel.send("fill", locals_to_params(locals()))
  File "/opt/hostedtoolcache/Python/3.11.12/x64/lib/python3.11/site-packages/playwright/_impl/_connection.py", line 61, in send
    return await self._connection.wrap_api_call(
           ^^^^^^^^^^^^^^^^^^^^^^^^^^^^^^^^^^^^^
  File "/opt/hostedtoolcache/Python/3.11.12/x64/lib/python3.11/site-packages/playwright/_impl/_connection.py", line 528, in wrap_api_call
    raise rewrite_error(error, f"{parsed_st['apiName']}: {error}") from None
playwright._impl._errors.TimeoutError: Page.fill: Timeout 30000ms exceeded.
Call log:
  - waiting for locator("input[type=\"email\"]")

Error: Process completed with exit code 1.
