C:\Users\sethurajan.r\Desktop\tamil_news>python main.py
Traceback (most recent call last):
  File "C:\Users\sethurajan.r\AppData\Roaming\Python\Python313\site-packages\urllib3\connection.py", line 198, in _new_conn
    sock = connection.create_connection(
        (self._dns_host, self.port),
    ...<2 lines>...
        socket_options=self.socket_options,
    )
  File "C:\Users\sethurajan.r\AppData\Roaming\Python\Python313\site-packages\urllib3\util\connection.py", line 60, in create_connection
    for res in socket.getaddrinfo(host, port, family, socket.SOCK_STREAM):
               ~~~~~~~~~~~~~~~~~~^^^^^^^^^^^^^^^^^^^^^^^^^^^^^^^^^^^^^^^^
  File "C:\Program Files\Python313\Lib\socket.py", line 977, in getaddrinfo
    for res in _socket.getaddrinfo(host, port, family, type, proto, flags):
               ~~~~~~~~~~~~~~~~~~~^^^^^^^^^^^^^^^^^^^^^^^^^^^^^^^^^^^^^^^^
socket.gaierror: [Errno 11001] getaddrinfo failed

The above exception was the direct cause of the following exception:

Traceback (most recent call last):
  File "C:\Users\sethurajan.r\AppData\Roaming\Python\Python313\site-packages\urllib3\connectionpool.py", line 787, in urlopen
    response = self._make_request(
        conn,
    ...<10 lines>...
        **response_kw,
    )
  File "C:\Users\sethurajan.r\AppData\Roaming\Python\Python313\site-packages\urllib3\connectionpool.py", line 488, in _make_request
    raise new_e
  File "C:\Users\sethurajan.r\AppData\Roaming\Python\Python313\site-packages\urllib3\connectionpool.py", line 464, in _make_request
    self._validate_conn(conn)
    ~~~~~~~~~~~~~~~~~~~^^^^^^
  File "C:\Users\sethurajan.r\AppData\Roaming\Python\Python313\site-packages\urllib3\connectionpool.py", line 1093, in _validate_conn
    conn.connect()
    ~~~~~~~~~~~~^^
  File "C:\Users\sethurajan.r\AppData\Roaming\Python\Python313\site-packages\urllib3\connection.py", line 704, in connect
    self.sock = sock = self._new_conn()
                       ~~~~~~~~~~~~~~^^
  File "C:\Users\sethurajan.r\AppData\Roaming\Python\Python313\site-packages\urllib3\connection.py", line 205, in _new_conn
    raise NameResolutionError(self.host, self, e) from e
urllib3.exceptions.NameResolutionError: <urllib3.connection.HTTPSConnection object at 0x000001B1DF688050>: Failed to resolve 'api.mail.tm' ([Errno 11001] getaddrinfo failed)

The above exception was the direct cause of the following exception:

Traceback (most recent call last):
  File "C:\Users\sethurajan.r\AppData\Roaming\Python\Python313\site-packages\requests\adapters.py", line 486, in send
    resp = conn.urlopen(
        method=request.method,
    ...<9 lines>...
        chunked=chunked,
    )
  File "C:\Users\sethurajan.r\AppData\Roaming\Python\Python313\site-packages\urllib3\connectionpool.py", line 841, in urlopen
    retries = retries.increment(
        method, url, error=new_e, _pool=self, _stacktrace=sys.exc_info()[2]
    )
  File "C:\Users\sethurajan.r\AppData\Roaming\Python\Python313\site-packages\urllib3\util\retry.py", line 519, in increment
    raise MaxRetryError(_pool, url, reason) from reason  # type: ignore[arg-type]
    ^^^^^^^^^^^^^^^^^^^^^^^^^^^^^^^^^^^^^^^^^^^^^^^^^^^
urllib3.exceptions.MaxRetryError: HTTPSConnectionPool(host='api.mail.tm', port=443): Max retries exceeded with url: /domains (Caused by NameResolutionError("<urllib3.connection.HTTPSConnection object at 0x000001B1DF688050>: Failed to resolve 'api.mail.tm' ([Errno 11001] getaddrinfo failed)"))

During handling of the above exception, another exception occurred:

Traceback (most recent call last):
  File "C:\Users\sethurajan.r\Desktop\tamil_news\main.py", line 38, in <module>
    main()
    ~~~~^^
  File "C:\Users\sethurajan.r\Desktop\tamil_news\main.py", line 9, in main
    mail_client = MailTMClient()
  File "C:\Users\sethurajan.r\Desktop\tamil_news\src\mailtm_client.py", line 8, in __init__
    self.account = self.create_account()
                   ~~~~~~~~~~~~~~~~~~~^^
  File "C:\Users\sethurajan.r\Desktop\tamil_news\src\mailtm_client.py", line 12, in create_account
    domain = self.session.get(f'{self.base_url}/domains', verify=False).json()['hydra:member'][0]['domain']
             ~~~~~~~~~~~~~~~~^^^^^^^^^^^^^^^^^^^^^^^^^^^^^^^^^^^^^^^^^^
  File "C:\Users\sethurajan.r\AppData\Roaming\Python\Python313\site-packages\requests\sessions.py", line 602, in get
    return self.request("GET", url, **kwargs)
           ~~~~~~~~~~~~^^^^^^^^^^^^^^^^^^^^^^
  File "C:\Users\sethurajan.r\AppData\Roaming\Python\Python313\site-packages\requests\sessions.py", line 589, in request
    resp = self.send(prep, **send_kwargs)
  File "C:\Users\sethurajan.r\AppData\Roaming\Python\Python313\site-packages\requests\sessions.py", line 703, in send
    r = adapter.send(request, **kwargs)
  File "C:\Users\sethurajan.r\AppData\Roaming\Python\Python313\site-packages\requests\adapters.py", line 519, in send
    raise ConnectionError(e, request=request)
requests.exceptions.ConnectionError: HTTPSConnectionPool(host='api.mail.tm', port=443): Max retries exceeded with url: /domains (Caused by NameResolutionError("<urllib3.connection.HTTPSConnection object at 0x000001B1DF688050>: Failed to resolve 'api.mail.tm' ([Errno 11001] getaddrinfo failed)"))
